Workbook

Sheet Parts List
A1: DAC3 Prototype — Bill of Materials
A2: Project status snapshot — totals roll up from the rows below; see the Summary tab for breakdowns.
A4: # | B4: Subsystem | C4: Part Number | D4: Description | E4: Vendor | F4: Mfr part # | G4: JLCPCB part # | H4: Qty | I4: Unit Price | J4: Total | K4: Status | L4: Order Date | M4: Notes
A5: 1 | B5: FPGA | C5: Cmod A7-35T | D5: Artix-7 XC7A35T module (testbed + final converter) | E5: Digilent | H5: 1 | I5: 99 | J5: =H5*I5 -> 99 | K5: Selected | M5: Selected for GTP transceivers; eliminates external PHY
A6: 2 | B6: Switch | C6: PMV16XN | D6: N-ch MOSFET, SOT-23, Vth=0.4V, Ron=80mΩ | E6: Mouser | H6: 224 | J6: =H6*I6 -> 0 | K6: Selected | M6: 56 MOSFETs × 4 modules = 224; sign-magnitude balanced
A7: 3 | B7: Switch | C7: ICL7660 | D7: Charge pump for negative rail level shifter | E7: Mouser | H7: 1 | J7: =H7*I7 -> 0 | K7: Selected | M7: Shared across all 28 negative-side signals
A8: 4 | B8: Switch | C8: 74LVCH16T245 | D8: 16-bit level shifter (negative-side) | E8: Mouser | G8: C426713 | H8: 12 | I8: 0.3989 | J8: =H8*I8 -> 4.7868 | K8: Selected | M8: Two devices feed the 28 negative-side gates
A9: 5 | B9: Vref | C9: LT3042 | D9: Positive precision LDO, 0.8nV/√Hz, trimmed to +2.5V | E9: Mouser | H9: 2 | J9: =H9*I9 -> 0 | K9: Selected | M9: Standalone positive Vref
A10: 6 | B10: Vref | C10: LT3094 | D10: Negative precision LDO, 2nV/√Hz, trimmed to −2.5V | E10: Mouser | H10: 2 | J10: =H10*I10 -> 0 | K10: Selected | M10: Standalone negative Vref
A11: 7 | B11: Vref | C11: LT6657-2.5 | D11: 2.5V metrology reference (FPGA ADC calibration) | E11: Mouser | H11: 1 | J11: =H11*I11 -> 0 | K11: Selected | M11: Reserved for calibration only; NOT in supply path
A12: 8 | B12: PSU | C12: LT3080 | D12: Adjustable LDO, TO-263 (0.8nV/√Hz) | E12: Mouser | H12: 5 | J12: =H12*I12 -> 0 | K12: Candidate | M12: 5× 3-terminal regs in PSU chassis (±Vref L/R + digital)
A13: 9 | B13: PSU | C13: Toroidal transformer | D13: Custom toroid for PSU chassis (CLCLC filter) | E13: Plitron | H13: 1 | J13: =H13*I13 -> 0 | K13: Pending | M13: AC primary → CLCLC → linear regs
A14: 10 | B14: R-2R Ladder | C14: Precision resistor 150Ω | D14: Thin-film precision R, R=150Ω (R-2R ladder) | E14: Mouser | H14: 256 | J14: =H14*I14 -> 0 | K14: Selected | M14: Ladder R=150Ω; quantity per 4× 16-bit modules
A15: 11 | B15: R-2R Ladder | C15: 74HC595 | D15: 8-bit shift register (testbed v2 only) | E15: Mouser | H15: 8 | J15: =H15*I15 -> 0 | K15: Selected | M15: Testbed v2 R-2R modules; final build uses PMV16XN direct drive
A16: 12 | B16: Output | C16: Mute relay | D16: DPDT signal relay for output mute on power transient | E16: Mouser | H16: 1 | J16: =H16*I16 -> 0 | K16: Pending | M16: Shorts output to GND during power-up/down; RC-delayed ~2-3s release
A17: 13 | B17: Output | C17: Output filter caps | D17: 3–5nF shunt cap for 2nd-order RC filter (pole ~100kHz) | E17: Mouser | H17: 4 | J17: =H17*I17 -> 0 | K17: Pending | M17: 75Ω ladder Thevenin + 150–220Ω series + this cap
A18: 14 | B18: Output | C18: Output filter R | D18: 150–220Ω series resistor (2nd-order RC filter) | E18: Mouser | H18: 4 | J18: =H18*I18 -> 0 | K18: Pending | M18: Pairs with shunt cap above
A19: 15 | B19: Connectors | C19: 61301221821 | D19: Wurth WR-PHD socket, 12-pin 2-row, 2.54mm | E19: Mouser | H19: 16 | J19: =H19*I19 -> 0 | K19: Selected | M19: Module-to-motherboard sockets; 2 per module × 8 modules
A20: 16 | B20: Connectors | C20: 61301221021 | D20: Wurth WR-PHD right-angle header, 12-pin 2-row, 2.54mm | E20: Mouser | H20: 16 | J20: =H20*I20 -> 0 | K20: Selected | M20: Mating header for module board edge
... A26: 22 | B26: Chassis | C26: Aluminum enclosure | D26: PSU chassis (TBD dimensions) | E26: Hammond | H26: 1 | J26: =H26*I26 -> 0 | K26: Pending | M26: Houses AC, transformer, CLCLC, linear regs
J27: =IF(OR(H27="",I27=""),"",H27*I27)
J28: =IF(OR(H28="",I28=""),"",H28*I28)
J29: =IF(OR(H29="",I29=""),"",H29*I29)
J30: =IF(OR(H30="",I30=""),"",H30*I30)
J31: =IF(OR(H31="",I31=""),"",H31*I31)
J32: =IF(OR(H32="",I32=""),"",H32*I32)
J33: =IF(OR(H33="",I33=""),"",H33*I33)
J34: =IF(OR(H34="",I34=""),"",H34*I34)
J35: =IF(OR(H35="",I35=""),"",H35*I35)
J36: =IF(OR(H36="",I36=""),"",H36*I36)
J37: =IF(OR(H37="",I37=""),"",H37*I37)
J38: =IF(OR(H38="",I38=""),"",H38*I38)
... J56: =IF(OR(H56="",I56=""),"",H56*I56)
B58: TOTAL | H58: =SUM(H5:H56) -> 562 | J58: =SUM(J5:J56) -> 103.7868

Sheet Prototype
A1: DAC3 Prototype Build — Sign-Magnitude SE, 21-bit, 4 Converter Primitives
A2: Soekris-style: 4 ladders (R+, R-, L+, L-) × 21 bits. Single-value 1.00kΩ 0.01% topology — 1× resistor as the 2R rung, 2× resistors in parallel as the R series link. Ratio 1:2 by construction, R_ladder=500Ω. 3× 74LVC595 per ladder, 7-of-8 outputs used. Validates FPGA chain & analog stage before the full Cascade build.
A4: # | B4: Subsystem | C4: Part Number | D4: Description | E4: Vendor | F4: Mfr part # | G4: JLCPCB part # | H4: Qty | I4: Unit Price | J4: Total | K4: Status | L4: Order Date | M4: Notes
A5: 1 | B5: FPGA | C5: Cmod A7-35T | D5: Artix-7 XC7A35T module (shared platform w/ final build) | E5: Digilent | H5: 1 | I5: 99 | J5: =H5*I5 -> 99 | K5: Selected | M5: Good capability for proto motherboard and all peripherals on-board and working.
A6: 2 | B6: Switch | C6: SN74LVC595APW,118 | D6: 8-bit serial shift register, low-Ron (~25Ω @ 3V), TSSOP-16 | E6: Mouser or JLCPCB | G6: C426713 | H6: 12 | I6: 0.3989 | J6: =H6*I6 -> 4.7868 | K6: Selected | M6: 3 per converter × 4 = 12; 7 of 8 outputs used (Denafrips-style)
A7: 3 | B7: R-2R Ladder | C7: R 1.00kΩ 0.01% — single value | D7: Thin-film precision, 1.00kΩ, 0.01% (e.g. Vishay TX2575 / Susumu RG). Used as: 2R rung (single) + R series link (2 in parallel = 500Ω). Ratio exact by construction. | E7: Mouser / JLCPCB consign | H7: 252 | J7: =H7*I7 -> 0 | K7: Selected | M7: Per ladder: 21 single-2R + 21 paired-R (42 parts) = 63 parts. ×4 ladders = 252.
A8: 4 | B8: R-2R Ladder | C8: R 1.00kΩ 0.01% — match spares | D8: Hand-match spares for binning MSB rungs into precision pairs | E8: Mouser / JLCPCB consign | H8: 48 | J8: =H8*I8 -> 0 | K8: Pending | M8: ~20% spare allowance for MSB hand-matching; bench-bin into ≤5ppm pairs before assembly
A9: 5 | B9: R-2R Ladder | C9: R 1.00kΩ 0.02% (alt) | D9: Fallback at 0.02% if 0.01% consignment logistics prove painful | E9: JLCPCB | H9: 0 | J9: =H9*I9 -> 0 | K9: Cancelled | M9: Direct from JLCPCB catalog; same single-value topology, same qty 252+48 if used
A10: 6 | B10: Vref | C10: LT3042 | D10: Positive precision LDO, 0.8nV/√Hz, +2.5V — 595 Vcc for +ladders | E10: Mouser | H10: 2 | J10: =H10*I10 -> 0 | K10: Selected | M10: Powers Vcc of 595s on R+/L+ ladders
A11: 7 | B11: Vref | C11: LT3094 | D11: Negative precision LDO, 2nV/√Hz, −2.5V — 595 Vcc for −ladders | E11: Mouser | H11: 2 | J11: =H11*I11 -> 0 | K11: Selected | M11: Inverted rail for R−/L− ladders
A12: 8 | B12: Vref | C12: LT6657-2.5 | D12: 2.5V metrology reference (FPGA ADC calibration only) | E12: Mouser | H12: 1 | J12: =H12*I12 -> 0 | K12: Selected | M12: NOT in supply path — calibration reference
A13: 9 | B13: Analog | C13: OPA1612 (or eq.) | D13: Audio op-amp for I/V or buffer stage | E13: Mouser | H13: 4 | J13: =H13*I13 -> 0 | K13: Pending | M13: One per converter primitive; selection TBD
A14: 10 | B14: Analog | C14: Diff-to-SE summer | D14: Op-amp + matched Rs for R+ minus R− (single-ended output) | E14: Mouser | H14: 2 | J14: =H14*I14 -> 0 | K14: Pending | M14: One per channel; sums sign-magnitude to SE
A15: 11 | B15: Output | C15: Mute relay | D15: DPDT signal relay, RC-delayed release (~2-3s) | E15: Mouser | H15: 1 | J15: =H15*I15 -> 0 | K15: Pending | M15: Protects downstream 4P1L tube from startup transients
A16: 12 | B16: Output | C16: Output filter cap | D16: 3-5nF shunt, 2nd-order RC, pole ~100kHz | E16: Mouser | H16: 2 | J16: =H16*I16 -> 0 | K16: Pending | M16: One per channel (SE output)
A17: 13 | B17: Output | C17: Output filter R | D17: 150-220Ω series for 2nd-order RC filter | E17: Mouser | H17: 2 | J17: =H17*I17 -> 0 | K17: Pending | M17: Pairs with shunt cap
A18: 14 | B18: Output | C18: RCA output jacks | D18: Audiophile RCA, DC-coupled | E18: Mouser | H18: 2 | J18: =H18*I18 -> 0 | K18: Pending | M18: L/R single-ended out
... A26: 22 | B26: Connectors | C26: Cmod A7 headers | D26: 2.54mm 24-pin headers for Cmod A7-35T board edge | E26: Mouser | H26: 2 | J26: =H26*I26 -> 0 | K26: Pending | M26: FPGA module-to-main-PCB mating
A27: 23 | B27: R-2R Ladder | C27: R 499 ohms 0.01% - single value | D27: Thin Film Resistors - SMD 499Ohms 0603 5ppm 0.01% Precision AEC-Q200 | E27: Mouser | G27: 708-RNCF0603TKY499R | H27: 300 | I27: 1.03 | J27: =IF(OR(H27="",I27=""),"",H27*I27) -> 309 | M27: 2R ladder rungs made from 2x series R - better for layout, other reasons.
B28: Ladder Trim | C28: R 10 ohms 1% | D28: R 10 ohms 1%, 0402 -55℃~+155℃ 10Ω 50V 62.5mW Thick Film Resistor ±1% ±200ppm/℃ 0402 Chip Resistor - Surface Mount ROHS | E28: JLCPCB | G28: C25077 | H28: =8*4 -> 32 | I28: 0.007 | J28: =IF(OR(H28="",I28=""),"",H28*I28) -> 0.224 | M28: Use on 8 msbs to get most of the benefit
J29: =IF(OR(H29="",I29=""),"",H29*I29)
J30: =IF(OR(H30="",I30=""),"",H30*I30)
J31: =IF(OR(H31="",I31=""),"",H31*I31)
J32: =IF(OR(H32="",I32=""),"",H32*I32)
J33: =IF(OR(H33="",I33=""),"",H33*I33)
J34: =IF(OR(H34="",I34=""),"",H34*I34)
J35: =IF(OR(H35="",I35=""),"",H35*I35)
J36: =IF(OR(H36="",I36=""),"",H36*I36)
J37: =IF(OR(H37="",I37=""),"",H37*I37)
J38: =IF(OR(H38="",I38=""),"",H38*I38)
J39: =IF(OR(H39="",I39=""),"",H39*I39)
J40: =IF(OR(H40="",I40=""),"",H40*I40)
... J51: =IF(OR(H51="",I51=""),"",H51*I51)
B53: TOTAL | H53: =SUM(H5:H51) -> 676 | J53: =SUM(J5:J51) -> 413.0108

Sheet Summary
A1: DAC3 Prototype — Summary
A3: Line items | B3: Total parts (qty) | C3: Project cost | D3: Avg unit price | E3: Vendors used
A4: =COUNTA('Parts List'!C5:C56) -> 22 | B4: =SUM('Parts List'!H5:H56) -> 562 | C4: =SUM('Parts List'!J5:J56) -> 103.7868 | D4: =IFERROR(C4/B4,0) -> 0.18467402 | E4: =SUMPRODUCT((('Parts List'!E5:E56<>"")/COUNTIF('Parts List'!E5:E56,'Parts List'!E5:E56&""))) -> 5
A6: By Status
A7: Status | B7: Line items | C7: Cost
A8: Pending | B8: =COUNTIF('Parts List'!K5:K56,A8) -> 10 | C8: =SUMIF('Parts List'!K5:K56,A8,'Parts List'!J5:J56) -> 0
A9: Candidate | B9: =COUNTIF('Parts List'!K5:K56,A9) -> 1 | C9: =SUMIF('Parts List'!K5:K56,A9,'Parts List'!J5:J56) -> 0
A10: Selected | B10: =COUNTIF('Parts List'!K5:K56,A10) -> 11 | C10: =SUMIF('Parts List'!K5:K56,A10,'Parts List'!J5:J56) -> 103.7868
A11: Quoted | B11: =COUNTIF('Parts List'!K5:K56,A11) -> 0 | C11: =SUMIF('Parts List'!K5:K56,A11,'Parts List'!J5:J56) -> 0
A12: Ordered | B12: =COUNTIF('Parts List'!K5:K56,A12) -> 0 | C12: =SUMIF('Parts List'!K5:K56,A12,'Parts List'!J5:J56) -> 0
A13: Received | B13: =COUNTIF('Parts List'!K5:K56,A13) -> 0 | C13: =SUMIF('Parts List'!K5:K56,A13,'Parts List'!J5:J56) -> 0
A14: Installed | B14: =COUNTIF('Parts List'!K5:K56,A14) -> 0 | C14: =SUMIF('Parts List'!K5:K56,A14,'Parts List'!J5:J56) -> 0
A15: Tested | B15: =COUNTIF('Parts List'!K5:K56,A15) -> 0 | C15: =SUMIF('Parts List'!K5:K56,A15,'Parts List'!J5:J56) -> 0
A16: Cancelled | B16: =COUNTIF('Parts List'!K5:K56,A16) -> 0 | C16: =SUMIF('Parts List'!K5:K56,A16,'Parts List'!J5:J56) -> 0
A18: By Subsystem
A19: Subsystem | B19: Line items | C19: Cost
A20: FPGA | B20: =COUNTIF('Parts List'!B5:B56,A20) -> 1 | C20: =SUMIF('Parts List'!B5:B56,A20,'Parts List'!J5:J56) -> 99
A21: Switch | B21: =COUNTIF('Parts List'!B5:B56,A21) -> 3 | C21: =SUMIF('Parts List'!B5:B56,A21,'Parts List'!J5:J56) -> 4.7868
A22: Vref | B22: =COUNTIF('Parts List'!B5:B56,A22) -> 3 | C22: =SUMIF('Parts List'!B5:B56,A22,'Parts List'!J5:J56) -> 0
A23: PSU | B23: =COUNTIF('Parts List'!B5:B56,A23) -> 2 | C23: =SUMIF('Parts List'!B5:B56,A23,'Parts List'!J5:J56) -> 0
A24: R-2R Ladder | B24: =COUNTIF('Parts List'!B5:B56,A24) -> 2 | C24: =SUMIF('Parts List'!B5:B56,A24,'Parts List'!J5:J56) -> 0
A25: Output | B25: =COUNTIF('Parts List'!B5:B56,A25) -> 3 | C25: =SUMIF('Parts List'!B5:B56,A25,'Parts List'!J5:J56) -> 0
A26: Connectors | B26: =COUNTIF('Parts List'!B5:B56,A26) -> 3 | C26: =SUMIF('Parts List'!B5:B56,A26,'Parts List'!J5:J56) -> 0
A27: Inputs | B27: =COUNTIF('Parts List'!B5:B56,A27) -> 3 | C27: =SUMIF('Parts List'!B5:B56,A27,'Parts List'!J5:J56) -> 0
A28: Chassis | B28: =COUNTIF('Parts List'!B5:B56,A28) -> 2 | C28: =SUMIF('Parts List'!B5:B56,A28,'Parts List'!J5:J56) -> 0
A29: Misc | B29: =COUNTIF('Parts List'!B5:B56,A29) -> 0 | C29: =SUMIF('Parts List'!B5:B56,A29,'Parts List'!J5:J56) -> 0
A31: By Vendor
A32: Vendor | B32: Line items | C32: Cost
A33: JLCPCB | B33: =COUNTIF('Parts List'!E5:E56,A33) -> 0 | C33: =SUMIF('Parts List'!E5:E56,A33,'Parts List'!J5:J56) -> 0
A34: Mouser | B34: =COUNTIF('Parts List'!E5:E56,A34) -> 17 | C34: =SUMIF('Parts List'!E5:E56,A34,'Parts List'!J5:J56) -> 4.7868
A35: LCSC | B35: =COUNTIF('Parts List'!E5:E56,A35) -> 0 | C35: =SUMIF('Parts List'!E5:E56,A35,'Parts List'!J5:J56) -> 0
A36: Digi-Key | B36: =COUNTIF('Parts List'!E5:E56,A36) -> 0 | C36: =SUMIF('Parts List'!E5:E56,A36,'Parts List'!J5:J56) -> 0
A37: Digilent | B37: =COUNTIF('Parts List'!E5:E56,A37) -> 1 | C37: =SUMIF('Parts List'!E5:E56,A37,'Parts List'!J5:J56) -> 99
A38: Plitron | B38: =COUNTIF('Parts List'!E5:E56,A38) -> 1 | C38: =SUMIF('Parts List'!E5:E56,A38,'Parts List'!J5:J56) -> 0
A39: Hammond | B39: =COUNTIF('Parts List'!E5:E56,A39) -> 2 | C39: =SUMIF('Parts List'!E5:E56,A39,'Parts List'!J5:J56) -> 0
A40: Lemo | B40: =COUNTIF('Parts List'!E5:E56,A40) -> 1 | C40: =SUMIF('Parts List'!E5:E56,A40,'Parts List'!J5:J56) -> 0
A41: Other | B41: =COUNTIF('Parts List'!E5:E56,A41) -> 0 | C41: =SUMIF('Parts List'!E5:E56,A41,'Parts List'!J5:J56) -> 0
A44: How to use this workbook
A45: • Add a part: fill the next blank row on Parts List. Subsystem and Status both have dropdowns.
A46: • Total column auto-calculates from Qty × Unit Price; blank rows stay empty until you fill them in.
...
